<?xml version="1.0" ?>
<!-- =================================================================================== -->
<!-- |    This document was autogenerated by xacro from exo.xacro                      | -->
<!-- |    EDITING THIS FILE BY HAND IS NOT RECOMMENDED                                 | -->
<!-- =================================================================================== -->
<robot name="exo">
  <material name="silver">
    <color rgba="0.8 0.8 0.8 1.0"/>
  </material>
  <material name="blue">
    <color rgba="0.8 1 0.8 1.0"/>
  </material>
  <material name="green">
    <color rgba="0.8 0.8 1 1.0"/>
  </material>
  <!-- Human Boday Paramters -->
  
\
  
  <link name="d435_front">
    <collision>
      <origin rpy="0 0 0" xyz="0 0 0"/>
      <geometry>
        <box size="0.025 0.05 0.025"/>
      </geometry>
    </collision>
    <visual>
      <origin rpy="0 0 0" xyz="0 0 0"/>
      <geometry>
        <box size="0.0125 0.05 0.025"/>
      </geometry>
      <material name="red"/>
    </visual>
    <inertial>
      <mass value="1e-5"/>
      <origin rpy="0 0 0" xyz="0 0 0"/>
      <inertia ixx="1e-6" ixy="0" ixz="0" iyy="1e-6" iyz="0" izz="1e-6"/>
    </inertial>
  </link>
  <joint name="d435_front_joint" type="fixed">
    <axis xyz="0 1 0"/>
    <origin rpy="0 0.0 0" xyz="0.05 0 -0.234"/>
    <parent link="l_thigh_link"/>
    <child link="d435_front"/>
  </joint>
  <gazebo reference="d435_front">
    <sensor name="d435_front" type="depth">
      <always_on>true</always_on>
      <visualize>false</visualize>
      <camera>
        <horizontal_fov>1.3439</horizontal_fov>
        <image>
          <width>1920</width>
          <height>1080</height>
          <format>R8G8B8</format>
        </image>
        <depth_camera/>
        <clip>
          <near>0.03</near>
          <far>100</far>
        </clip>
      </camera>
      <plugin filename="libgazebo_ros_openni_kinect.so" name="camera_controller">
        <baseline>0.2</baseline>
        <alwaysOn>true</alwaysOn>
        <updateRate>30.0</updateRate>
        <cameraName>d435_front</cameraName>
        <frameName>d435_front</frameName>
        <imageTopicName>d435_front/rgb/image_raw</imageTopicName>
        <depthImageTopicName>d435_front/depth/image_raw</depthImageTopicName>
        <pointCloudTopicName>d435_front/depth/points</pointCloudTopicName>
        <cameraInfoTopicName>d435_front/rgb/camera_info</cameraInfoTopicName>
        <depthImageCameraInfoTopicName>d435_front/depth/camera_info</depthImageCameraInfoTopicName>
        <pointCloudCutoff>0.1</pointCloudCutoff>
        <hackBaseline>0.01</hackBaseline>
        <distortionK1>0.0</distortionK1>
        <distortionK2>0.0</distortionK2>
        <distortionK3>0.0</distortionK3>
        <distortionT1>0.0</distortionT1>
        <distortionT2>0.0</distortionT2>
        <CxPrime>0.0</CxPrime>
        <Cx>0.0</Cx>
        <Cy>0.0</Cy>
        <focalLength>0</focalLength>
        <hackBaseline>0</hackBaseline>
      </plugin>
    </sensor>
  </gazebo>
  <link name="d435_back">
    <collision>
      <origin rpy="0 0 0" xyz="0 0 0"/>
      <geometry>
        <box size="0.025 0.05 0.025"/>
      </geometry>
    </collision>
    <visual>
      <origin rpy="0 0 0" xyz="0 0 0"/>
      <geometry>
        <box size="0.0125 0.05 0.025"/>
      </geometry>
      <material name="red"/>
    </visual>
    <inertial>
      <mass value="1e-5"/>
      <origin rpy="0 0 0" xyz="0 0 0"/>
      <inertia ixx="1e-6" ixy="0" ixz="0" iyy="1e-6" iyz="0" izz="1e-6"/>
    </inertial>
  </link>
  <joint name="d435_back_joint" type="fixed">
    <axis xyz="0 1 0"/>
    <origin rpy="0 0 3.141592653589793" xyz="-0.05 0 -0.234"/>
    <parent link="l_thigh_link"/>
    <child link="d435_back"/>
  </joint>
  <gazebo reference="d435_back">
    <sensor name="d435_back" type="depth">
      <always_on>true</always_on>
      <visualize>false</visualize>
      <camera>
        <horizontal_fov>1.3439</horizontal_fov>
        <image>
          <width>1920</width>
          <height>1080</height>
          <format>R8G8B8</format>
        </image>
        <depth_camera/>
        <clip>
          <near>0.03</near>
          <far>100</far>
        </clip>
      </camera>
      <plugin filename="libgazebo_ros_openni_kinect.so" name="camera_controller">
        <baseline>0.2</baseline>
        <alwaysOn>true</alwaysOn>
        <updateRate>30.0</updateRate>
        <cameraName>d435_back</cameraName>
        <frameName>d435_back</frameName>
        <imageTopicName>d435_back/rgb/image_raw</imageTopicName>
        <depthImageTopicName>d435_back/depth/image_raw</depthImageTopicName>
        <pointCloudTopicName>d435_back/depth/points</pointCloudTopicName>
        <cameraInfoTopicName>d435_back/rgb/camera_info</cameraInfoTopicName>
        <depthImageCameraInfoTopicName>d435_back/depth/camera_info</depthImageCameraInfoTopicName>
        <pointCloudCutoff>0.1</pointCloudCutoff>
        <hackBaseline>0.01</hackBaseline>
        <distortionK1>0.0</distortionK1>
        <distortionK2>0.0</distortionK2>
        <distortionK3>0.0</distortionK3>
        <distortionT1>0.0</distortionT1>
        <distortionT2>0.0</distortionT2>
        <CxPrime>0.0</CxPrime>
        <Cx>0.0</Cx>
        <Cy>0.0</Cy>
        <focalLength>0</focalLength>
        <hackBaseline>0</hackBaseline>
      </plugin>
    </sensor>
  </gazebo>
  <link name="world"/>
  <joint name="pole_to_waist" type="fixed">
    <parent link="world"/>
    <child link="waist_link"/>
    <origin rpy="0 0 0" xyz="0 0 0"/>
  </joint>
  <!-- 
  <link name="human_waist_link">
    <visual>
      <origin xyz="0 0 ${-human_waist_h/2}" rpy="0 0 0" />
      <geometry>
        <box size="${human_waist_l} ${human_waist_w} ${human_waist_h}" />
      </geometry>
      <material name="black" />
    </visual>
    <collision>
      <origin xyz="0 0 ${-human_waist_h/2}" rpy="0 0 0" />
      <geometry>
        <box size="${human_waist_l} ${human_waist_w} ${human_waist_h}" />
      </geometry>
    </collision>

    <inertial>
      <origin xyz="0 0 ${-human_waist_h/2}" rpy="0 0 0" />
      <mass value="${human_waist_weight}" />
      <inertia ixx="${human_waist_weight / 12.0 * (human_waist_w**2 + human_waist_h**2)}" iyy="${human_waist_weight / 12.0 * (human_waist_l**2 + human_waist_h**2)}" izz="${human_waist_weight / 12.0 * (human_waist_l**2 + human_waist_w**2)}" ixy="0" ixz="0" iyz="0" />
    </inertial>

  </link>

  <joint name="human_waist_link_joint" type="fixed">
    <parent link="waist_link" />
    <child link="human_waist_link" />
    <origin xyz="${human_waist_l/2 + 0.08} 0 ${0}" rpy="0 0 0" />
  </joint> -->
  <link name="waist_link">
    <collision>
      <origin rpy="0 0 0" xyz="0 0 -0.025"/>
      <geometry>
        <box size="0.05 0.225 0.03"/>
      </geometry>
    </collision>
    <visual>
      <!-- <xacro:if value="${use_mesh}">
                    <mesh_filename="" />
                </xacro:if> -->
      <!-- <xacro:property name="o_rpy_parts" value="split(o_rpy)" />
                <xacro:property name="o_yaw" value="${(o_rpy_parts[2])}" /> -->
      <!-- <origin xyz="0 0 0" rpy="0 0 ${-PI}" /> -->
      <!-- <origin xyz="${-h} ${-w/2} ${-l}" rpy="${PI/2} 0 ${PI/2 + float(o_yaw)}" /> -->
      <origin rpy="1.5707963267948966 0 -1.5707963267948966" xyz="0 0.21000000000000002 -0.062"/>
      <geometry>
        <mesh filename="package://yr_description/urdf/meshes_yr/waist_center.STL" scale="0.001 0.001 0.001"/>
      </geometry>
      <origin rpy="0 0 0" xyz="0 0 -0.025"/>
      <material name="silver"/>
    </visual>
    <inertial>
      <origin rpy="0 0 0" xyz="0 0 -0.025"/>
      <mass value="2.0"/>
      <inertia ixx="0.008854166666666666" ixy="0.0" ixz="0.0" iyy="0.0008333333333333335" iyz="0.0" izz="0.008854166666666666"/>
    </inertial>
  </link>
  <link name="l_pel_link">
    <collision>
      <origin rpy="0 0 0" xyz="0 0 -0.05"/>
      <geometry>
        <box size="0.1 0.05 0.06"/>
      </geometry>
    </collision>
    <visual>
      <!-- <xacro:if value="${use_mesh}">
                    <mesh_filename="" />
                </xacro:if> -->
      <!-- <xacro:property name="o_rpy_parts" value="split(o_rpy)" />
                <xacro:property name="o_yaw" value="${(o_rpy_parts[2])}" /> -->
      <!-- <origin xyz="0 0 0" rpy="0 0 ${-PI}" /> -->
      <!-- <origin xyz="${-h} ${-w/2} ${-l}" rpy="${PI/2} 0 ${PI/2 + float(o_yaw)}" /> -->
      <origin rpy="1.5707963267948966 0 1.5707963267948966" xyz="-0.09 -0.028 -0.088"/>
      <geometry>
        <mesh filename="package://yr_description/urdf/meshes_yr/waist_corner_bracket.STL" scale="0.001 0.001 0.001"/>
      </geometry>
      <origin rpy="0 0 0" xyz="0 0 -0.05"/>
      <material name="silver"/>
    </visual>
    <inertial>
      <origin rpy="0 0 0" xyz="0 0 -0.05"/>
      <mass value="1.0"/>
      <inertia ixx="0.0010416666666666669" ixy="0.0" ixz="0.0" iyy="0.001666666666666667" iyz="0.0" izz="0.0010416666666666669"/>
    </inertial>
  </link>
  <link name="l_thigh_link">
    <collision>
      <origin rpy="0 0 0" xyz="0 0 -0.234"/>
      <geometry>
        <box size="0.1 0.1 0.2808"/>
      </geometry>
    </collision>
    <visual>
      <!-- <xacro:if value="${use_mesh}">
                    <mesh_filename="" />
                </xacro:if> -->
      <!-- <xacro:property name="o_rpy_parts" value="split(o_rpy)" />
                <xacro:property name="o_yaw" value="${(o_rpy_parts[2])}" /> -->
      <!-- <origin xyz="0 0 0" rpy="0 0 ${-PI}" /> -->
      <!-- <origin xyz="${-h} ${-w/2} ${-l}" rpy="${PI/2} 0 ${PI/2 + float(o_yaw)}" /> -->
      <origin rpy="1.5707963267948966 0 4.71238898038469" xyz="0.1 0.05 -0.468"/>
      <geometry>
        <mesh filename="package://yr_description/urdf/meshes_yr/exo_thigh.STL" scale="0.001 0.001 0.001"/>
      </geometry>
      <origin rpy="0 0 0" xyz="0 0 -0.234"/>
      <material name="blue"/>
    </visual>
    <inertial>
      <origin rpy="0 0 0" xyz="0 0 -0.234"/>
      <mass value="1.5"/>
      <inertia ixx="0.028628000000000004" ixy="0.0" ixz="0.0" iyy="0.028628000000000004" iyz="0.0" izz="0.0025000000000000005"/>
    </inertial>
  </link>
  <link name="l_shank_link">
    <collision>
      <origin rpy="0 0 0" xyz="0 0 -0.234"/>
      <geometry>
        <box size="0.1 0.1 0.2808"/>
      </geometry>
    </collision>
    <visual>
      <!-- <xacro:if value="${use_mesh}">
                    <mesh_filename="" />
                </xacro:if> -->
      <!-- <xacro:property name="o_rpy_parts" value="split(o_rpy)" />
                <xacro:property name="o_yaw" value="${(o_rpy_parts[2])}" /> -->
      <!-- <origin xyz="0 0 0" rpy="0 0 ${-PI}" /> -->
      <!-- <origin xyz="${-h} ${-w/2} ${-l}" rpy="${PI/2} 0 ${PI/2 + float(o_yaw)}" /> -->
      <origin rpy="1.5707963267948966 0 4.71238898038469" xyz="0.1 0.05 -0.468"/>
      <geometry>
        <mesh filename="package://yr_description/urdf/meshes_yr/exo_shank.STL" scale="0.001 0.001 0.001"/>
      </geometry>
      <origin rpy="0 0 0" xyz="0 0 -0.234"/>
      <material name="green"/>
    </visual>
    <inertial>
      <origin rpy="0 0 0" xyz="0 0 -0.234"/>
      <mass value="1.5"/>
      <inertia ixx="0.028628000000000004" ixy="0.0" ixz="0.0" iyy="0.028628000000000004" iyz="0.0" izz="0.0025000000000000005"/>
    </inertial>
  </link>
  <!-- <xacro:create_link2 name="l_foot_link" m="${foot_m}" l="${foot_h}" w="${foot_w}" h="${foot_l}" o_x="${-foot_h}" o_y="${foot_w}" o_z="${-foot_l}" o_r="0" o_p="0" o_yaw="0" mat="${foot_mat}" mesh_filename="${foot_mesh}" mirror="-1" /> -->
  <link name="l_foot_link">
    <collision>
      <origin rpy="0 0 0" xyz="0.05 0 -0.1"/>
      <geometry>
        <box size="0.2 0.08 0.075"/>
      </geometry>
    </collision>
    <visual>
      <origin rpy="1.5707963267948966 0 1.5707963267948966" xyz="-0.1 0.08 -0.15"/>
      <geometry>
        <mesh filename="package://yr_description/urdf/meshes_yr/exo_foot.STL" scale="-0.001 0.001 0.001"/>
      </geometry>
      <origin rpy="0 0 0" xyz="0 0 -0.05"/>
      <material name="silver"/>
    </visual>
    <inertial>
      <origin rpy="0 0 0" xyz="0 0 -0.05"/>
      <mass value="1.0"/>
      <inertia ixx="0.0013666666666666666" ixy="0.0" ixz="0.0" iyy="0.0027083333333333334" iyz="0.0" izz="0.002408333333333333"/>
    </inertial>
  </link>
  <link name="l_foot_bottom_link">
    <!-- <collision>
      <origin xyz="0 0 0" rpy="0 0 0" />
      <geometry>
        <box size="0.01 0.01 0.01" />
      </geometry>
      <origin xyz="0 0 0" rpy="0 0 0" />
    </collision> -->
    <visual>
      <origin rpy="0 0 0" xyz="0 0 0"/>
      <geometry>
        <box size="0.01 0.01 0.01"/>
      </geometry>
      <origin rpy="0 0 0" xyz="0 0 0"/>
      <material name="silver"/>
    </visual>
    <inertial>
      <origin rpy="0 0 0" xyz="0 0 0"/>
      <mass value="0.01"/>
      <inertia ixx="0.00001" ixy="0.0" ixz="0.0" iyy="0.00001" iyz="0.0" izz="0.00001"/>
    </inertial>
  </link>
  <joint name="l_foot_bottom_joint" type="fixed">
    <parent link="l_foot_link"/>
    <child link="l_foot_bottom_link"/>
    <origin rpy="0 0 0" xyz="0.05 0 -0.14"/>
  </joint>
  <link name="r_pel_link">
    <collision>
      <origin rpy="0 0 0" xyz="0 0 -0.05"/>
      <geometry>
        <box size="0.1 0.05 0.06"/>
      </geometry>
    </collision>
    <visual>
      <!-- <xacro:if value="${use_mesh}">
                    <mesh_filename="" />
                </xacro:if> -->
      <!-- <xacro:property name="o_rpy_parts" value="split(o_rpy)" />
                <xacro:property name="o_yaw" value="${(o_rpy_parts[2])}" /> -->
      <!-- <origin xyz="0 0 0" rpy="0 0 ${-PI}" /> -->
      <!-- <origin xyz="${-h} ${-w/2} ${-l}" rpy="${PI/2} 0 ${PI/2 + float(o_yaw)}" /> -->
      <origin rpy="1.5707963267948966 0 1.5707963267948966" xyz="-0.09 -0.028 -0.088"/>
      <geometry>
        <mesh filename="package://yr_description/urdf/meshes_yr/waist_corner_bracket.STL" scale="0.001 0.001 0.001"/>
      </geometry>
      <origin rpy="0 0 0" xyz="0 0 -0.05"/>
      <material name="silver"/>
    </visual>
    <inertial>
      <origin rpy="0 0 0" xyz="0 0 -0.05"/>
      <mass value="1.0"/>
      <inertia ixx="0.0010416666666666669" ixy="0.0" ixz="0.0" iyy="0.001666666666666667" iyz="0.0" izz="0.0010416666666666669"/>
    </inertial>
  </link>
  <link name="r_thigh_link">
    <collision>
      <origin rpy="0 0 0" xyz="0 0 -0.234"/>
      <geometry>
        <box size="0.1 0.1 0.2808"/>
      </geometry>
    </collision>
    <visual>
      <!-- <xacro:if value="${use_mesh}">
                    <mesh_filename="" />
                </xacro:if> -->
      <!-- <xacro:property name="o_rpy_parts" value="split(o_rpy)" />
                <xacro:property name="o_yaw" value="${(o_rpy_parts[2])}" /> -->
      <!-- <origin xyz="0 0 0" rpy="0 0 ${-PI}" /> -->
      <!-- <origin xyz="${-h} ${-w/2} ${-l}" rpy="${PI/2} 0 ${PI/2 + float(o_yaw)}" /> -->
      <origin rpy="1.5707963267948966 0 1.5707963267948966" xyz="-0.1 -0.05 -0.468"/>
      <geometry>
        <mesh filename="package://yr_description/urdf/meshes_yr/exo_thigh.STL" scale="0.001 0.001 0.001"/>
      </geometry>
      <origin rpy="0 0 0" xyz="0 0 -0.234"/>
      <material name="blue"/>
    </visual>
    <inertial>
      <origin rpy="0 0 0" xyz="0 0 -0.234"/>
      <mass value="1.5"/>
      <inertia ixx="0.028628000000000004" ixy="0.0" ixz="0.0" iyy="0.028628000000000004" iyz="0.0" izz="0.0025000000000000005"/>
    </inertial>
  </link>
  <link name="r_shank_link">
    <collision>
      <origin rpy="0 0 0" xyz="0 0 -0.234"/>
      <geometry>
        <box size="0.1 0.1 0.2808"/>
      </geometry>
    </collision>
    <visual>
      <!-- <xacro:if value="${use_mesh}">
                    <mesh_filename="" />
                </xacro:if> -->
      <!-- <xacro:property name="o_rpy_parts" value="split(o_rpy)" />
                <xacro:property name="o_yaw" value="${(o_rpy_parts[2])}" /> -->
      <!-- <origin xyz="0 0 0" rpy="0 0 ${-PI}" /> -->
      <!-- <origin xyz="${-h} ${-w/2} ${-l}" rpy="${PI/2} 0 ${PI/2 + float(o_yaw)}" /> -->
      <origin rpy="1.5707963267948966 0 1.5707963267948966" xyz="-0.1 -0.05 -0.468"/>
      <geometry>
        <mesh filename="package://yr_description/urdf/meshes_yr/exo_shank.STL" scale="0.001 0.001 0.001"/>
      </geometry>
      <origin rpy="0 0 0" xyz="0 0 -0.234"/>
      <material name="green"/>
    </visual>
    <inertial>
      <origin rpy="0 0 0" xyz="0 0 -0.234"/>
      <mass value="1.5"/>
      <inertia ixx="0.028628000000000004" ixy="0.0" ixz="0.0" iyy="0.028628000000000004" iyz="0.0" izz="0.0025000000000000005"/>
    </inertial>
  </link>
  <!-- <xacro:create_link2 name="r_foot_link" m="${foot_m}" l="${foot_h}" w="${foot_w}" h="${foot_l}" o_x="${-foot_h}" o_y="${-foot_w}" o_z="${-foot_l}" o_r="0" o_p="0" o_yaw="0" mat="${foot_mat}" mesh_filename="${foot_mesh}" mirror="1" /> -->
  <link name="r_foot_link">
    <collision>
      <origin rpy="0 0 0" xyz="0.05 0 -0.1"/>
      <geometry>
        <box size="0.2 0.08 0.075"/>
      </geometry>
    </collision>
    <visual>
      <origin rpy="1.5707963267948966 0 1.5707963267948966" xyz="-0.1 -0.08 -0.15"/>
      <geometry>
        <mesh filename="package://yr_description/urdf/meshes_yr/exo_foot.STL" scale="0.001 0.001 0.001"/>
      </geometry>
      <origin rpy="0 0 0" xyz="0 0 -0.05"/>
      <material name="silver"/>
    </visual>
    <inertial>
      <origin rpy="0 0 0" xyz="0 0 -0.05"/>
      <mass value="1.0"/>
      <inertia ixx="0.0013666666666666666" ixy="0.0" ixz="0.0" iyy="0.0027083333333333334" iyz="0.0" izz="0.002408333333333333"/>
    </inertial>
  </link>
  <link name="r_foot_bottom_link">
    <!-- <collision>
      <origin xyz="0 0 0" rpy="0 0 0" />
      <geometry>
        <box size="0.01 0.01 0.01" />
      </geometry>
      <origin xyz="0 0 0" rpy="0 0 0" />
    </collision> -->
    <visual>
      <origin rpy="0 0 0" xyz="0 0 0"/>
      <geometry>
        <box size="0.01 0.01 0.01"/>
      </geometry>
      <origin rpy="0 0 0" xyz="0 0 0"/>
      <material name="silver"/>
    </visual>
    <inertial>
      <origin rpy="0 0 0" xyz="0 0 0"/>
      <mass value="0.01"/>
      <inertia ixx="0.00001" ixy="0.0" ixz="0.0" iyy="0.00001" iyz="0.0" izz="0.00001"/>
    </inertial>
  </link>
  <joint name="r_foot_bottom_joint" type="fixed">
    <parent link="r_foot_link"/>
    <child link="r_foot_bottom_link"/>
    <origin rpy="0 0 0" xyz="0.05 0 -0.14"/>
  </joint>
  <joint name="yr_l_pel_joint" type="revolute">
    <parent link="waist_link"/>
    <child link="l_pel_link"/>
    <origin rpy="-1.5707963267948966 0 -3.141592653589793" xyz="0 0.175 0"/>
    <axis xyz="1 0 0"/>
    <limit effort="1000" lower="-1.5707963267948966" upper="1.5707963267948966" velocity="10.0"/>
  </joint>
  <joint name="yr_l_hip_joint" type="revolute">
    <parent link="l_pel_link"/>
    <child link="l_thigh_link"/>
    <origin rpy="-1.5707963267948966 0 -3.141592653589793" xyz="-0.1 -0.025 -0.1"/>
    <axis xyz="0 1 0"/>
    <limit effort="1000" lower="-2.356194490192345" upper="2.356194490192345" velocity="10.0"/>
  </joint>
  <joint name="yr_l_kne_joint" type="revolute">
    <parent link="l_thigh_link"/>
    <child link="l_shank_link"/>
    <origin rpy="0 0 0" xyz="0 0 -0.468"/>
    <axis xyz="0 1 0"/>
    <limit effort="1000" lower="-0.7853981633974483" upper="3.141592653589793" velocity="10.0"/>
  </joint>
  <joint name="yr_l_ank_joint" type="revolute">
    <parent link="l_shank_link"/>
    <child link="l_foot_link"/>
    <origin rpy="0 0 0" xyz="0 0 -0.468"/>
    <axis xyz="0 1 0"/>
    <limit effort="1000" lower="-0.7853981633974483" upper="1.5707963267948966" velocity="10.0"/>
  </joint>
  <joint name="yr_r_pel_joint" type="revolute">
    <parent link="waist_link"/>
    <child link="r_pel_link"/>
    <origin rpy="1.5707963267948966 0 -3.141592653589793" xyz="0 -0.175 0"/>
    <axis xyz="1 0 0"/>
    <limit effort="1000" lower="-1.5707963267948966" upper="1.5707963267948966" velocity="10.0"/>
  </joint>
  <joint name="yr_r_hip_joint" type="revolute">
    <parent link="r_pel_link"/>
    <child link="r_thigh_link"/>
    <origin rpy="1.5707963267948966 0 -3.141592653589793" xyz="-0.1 0.025 -0.1"/>
    <axis xyz="0 1 0"/>
    <limit effort="1000" lower="-2.356194490192345" upper="2.356194490192345" velocity="10.0"/>
  </joint>
  <joint name="yr_r_kne_joint" type="revolute">
    <parent link="r_thigh_link"/>
    <child link="r_shank_link"/>
    <origin rpy="0 0 0" xyz="0 0 -0.468"/>
    <axis xyz="0 1 0"/>
    <limit effort="1000" lower="-0.7853981633974483" upper="3.141592653589793" velocity="10.0"/>
  </joint>
  <joint name="yr_r_ank_joint" type="revolute">
    <parent link="r_shank_link"/>
    <child link="r_foot_link"/>
    <origin rpy="0 0 0" xyz="0 0 -0.468"/>
    <axis xyz="0 1 0"/>
    <limit effort="1000" lower="-0.7853981633974483" upper="1.5707963267948966" velocity="10.0"/>
  </joint>
  <gazebo>
    <plugin filename="libgazebo_ros_control.so" name="gazebo_ros_control">
      <robotNamespace>/exo</robotNamespace>
      <robotSimType>gazebo_ros_control/DefaultRobotHWSim</robotSimType>
    </plugin>
  </gazebo>
  <transmission name="yr_l_pel_joint_tran">
    <type>transmission_interface/SimpleTransmission</type>
    <joint name="yr_l_pel_joint">
      <hardwareInterface>EffortJointInterface</hardwareInterface>
    </joint>
    <actuator name="yr_l_pel_joint_motor">
      <!-- <hardwareInterface>EffortJointInterface</hardwareInterface> -->
      <mechanicalReduction>1</mechanicalReduction>
    </actuator>
  </transmission>
  <transmission name="yr_l_hip_joint_tran">
    <type>transmission_interface/SimpleTransmission</type>
    <joint name="yr_l_hip_joint">
      <hardwareInterface>EffortJointInterface</hardwareInterface>
    </joint>
    <actuator name="yr_l_hip_joint_motor">
      <!-- <hardwareInterface>EffortJointInterface</hardwareInterface> -->
      <mechanicalReduction>1</mechanicalReduction>
    </actuator>
  </transmission>
  <transmission name="yr_l_kne_joint_tran">
    <type>transmission_interface/SimpleTransmission</type>
    <joint name="yr_l_kne_joint">
      <hardwareInterface>EffortJointInterface</hardwareInterface>
    </joint>
    <actuator name="yr_l_kne_joint_motor">
      <!-- <hardwareInterface>EffortJointInterface</hardwareInterface> -->
      <mechanicalReduction>1</mechanicalReduction>
    </actuator>
  </transmission>
  <transmission name="yr_l_ank_joint_tran">
    <type>transmission_interface/SimpleTransmission</type>
    <joint name="yr_l_ank_joint">
      <hardwareInterface>EffortJointInterface</hardwareInterface>
    </joint>
    <actuator name="yr_l_ank_joint_motor">
      <!-- <hardwareInterface>EffortJointInterface</hardwareInterface> -->
      <mechanicalReduction>1</mechanicalReduction>
    </actuator>
  </transmission>
  <transmission name="yr_r_pel_joint_tran">
    <type>transmission_interface/SimpleTransmission</type>
    <joint name="yr_r_pel_joint">
      <hardwareInterface>EffortJointInterface</hardwareInterface>
    </joint>
    <actuator name="yr_r_pel_joint_motor">
      <!-- <hardwareInterface>EffortJointInterface</hardwareInterface> -->
      <mechanicalReduction>1</mechanicalReduction>
    </actuator>
  </transmission>
  <transmission name="yr_r_hip_joint_tran">
    <type>transmission_interface/SimpleTransmission</type>
    <joint name="yr_r_hip_joint">
      <hardwareInterface>EffortJointInterface</hardwareInterface>
    </joint>
    <actuator name="yr_r_hip_joint_motor">
      <!-- <hardwareInterface>EffortJointInterface</hardwareInterface> -->
      <mechanicalReduction>1</mechanicalReduction>
    </actuator>
  </transmission>
  <transmission name="yr_r_kne_joint_tran">
    <type>transmission_interface/SimpleTransmission</type>
    <joint name="yr_r_kne_joint">
      <hardwareInterface>EffortJointInterface</hardwareInterface>
    </joint>
    <actuator name="yr_r_kne_joint_motor">
      <!-- <hardwareInterface>EffortJointInterface</hardwareInterface> -->
      <mechanicalReduction>1</mechanicalReduction>
    </actuator>
  </transmission>
  <transmission name="yr_r_ank_joint_tran">
    <type>transmission_interface/SimpleTransmission</type>
    <joint name="yr_r_ank_joint">
      <hardwareInterface>EffortJointInterface</hardwareInterface>
    </joint>
    <actuator name="yr_r_ank_joint_motor">
      <!-- <hardwareInterface>EffortJointInterface</hardwareInterface> -->
      <mechanicalReduction>1</mechanicalReduction>
    </actuator>
  </transmission>
  <gazebo reference="human_waist_link">
    <mu1>1.0</mu1>
    <mu2>1.0</mu2>
    <self_collide>0</self_collide>
    <material>Gazebo/White</material>
    <visual>
      <material>
        <ambient>0.7 0.7 0.7 1</ambient>
        <diffuse>0.7 0.7 0.7 1</diffuse>
        <specular>0.1 0.1 0.1 1</specular>
        <emissive>0 0 0 0</emissive>
      </material>
    </visual>
    <!-- <collision>
                <surface>
                    <friction>
                        <ode>
                            <mu1>2</mu1>
                            <mu2>2</mu2>
                            <kp value="1000000.0" />
                            <kd value="1000.0" />
                        </ode>
                    </friction>
                </surface>

            </collision> -->
  </gazebo>
  <gazebo reference="waist_link">
    <mu1>1.0</mu1>
    <mu2>1.0</mu2>
    <self_collide>0</self_collide>
    <material>Gazebo/White</material>
    <visual>
      <material>
        <ambient>0.7 0.7 0.7 1</ambient>
        <diffuse>0.7 0.7 0.7 1</diffuse>
        <specular>0.1 0.1 0.1 1</specular>
        <emissive>0 0 0 0</emissive>
      </material>
    </visual>
    <!-- <collision>
                <surface>
                    <friction>
                        <ode>
                            <mu1>2</mu1>
                            <mu2>2</mu2>
                            <kp value="1000000.0" />
                            <kd value="1000.0" />
                        </ode>
                    </friction>
                </surface>

            </collision> -->
  </gazebo>
  <gazebo reference="l_pel_link">
    <mu1>1.0</mu1>
    <mu2>1.0</mu2>
    <self_collide>0</self_collide>
    <material>Gazebo/White</material>
    <visual>
      <material>
        <ambient>0.7 0.7 0.7 1</ambient>
        <diffuse>0.7 0.7 0.7 1</diffuse>
        <specular>0.1 0.1 0.1 1</specular>
        <emissive>0 0 0 0</emissive>
      </material>
    </visual>
    <!-- <collision>
                <surface>
                    <friction>
                        <ode>
                            <mu1>2</mu1>
                            <mu2>2</mu2>
                            <kp value="1000000.0" />
                            <kd value="1000.0" />
                        </ode>
                    </friction>
                </surface>

            </collision> -->
  </gazebo>
  <gazebo reference="l_thigh_link">
    <mu1>1.0</mu1>
    <mu2>1.0</mu2>
    <self_collide>0</self_collide>
    <material>Gazebo/White</material>
    <visual>
      <material>
        <ambient>0.7 0.7 0.7 1</ambient>
        <diffuse>0.7 0.7 0.7 1</diffuse>
        <specular>0.1 0.1 0.1 1</specular>
        <emissive>0 0 0 0</emissive>
      </material>
    </visual>
    <!-- <collision>
                <surface>
                    <friction>
                        <ode>
                            <mu1>2</mu1>
                            <mu2>2</mu2>
                            <kp value="1000000.0" />
                            <kd value="1000.0" />
                        </ode>
                    </friction>
                </surface>

            </collision> -->
  </gazebo>
  <gazebo reference="l_shank_link">
    <mu1>1.0</mu1>
    <mu2>1.0</mu2>
    <self_collide>0</self_collide>
    <material>Gazebo/White</material>
    <visual>
      <material>
        <ambient>0.8 0.8 0.8 1</ambient>
        <diffuse>0.8 0.8 0.8 1</diffuse>
        <specular>0.1 0.1 0.1 1</specular>
        <emissive>0 0 0 0</emissive>
      </material>
    </visual>
    <!-- <collision>
                <surface>
                    <friction>
                        <ode>
                            <mu1>2</mu1>
                            <mu2>2</mu2>
                            <kp value="1000000.0" />
                            <kd value="1000.0" />
                        </ode>
                    </friction>
                </surface>

            </collision> -->
  </gazebo>
  <gazebo reference="l_foot_link">
    <mu1>1.0</mu1>
    <mu2>1.0</mu2>
    <self_collide>0</self_collide>
    <material>Gazebo/White</material>
    <visual>
      <material>
        <ambient>0.7 0.7 0.7 1</ambient>
        <diffuse>0.7 0.7 0.7 1</diffuse>
        <specular>0.1 0.1 0.1 1</specular>
        <emissive>0 0 0 0</emissive>
      </material>
    </visual>
    <!-- <collision>
                <surface>
                    <friction>
                        <ode>
                            <mu1>2</mu1>
                            <mu2>2</mu2>
                            <kp value="1000000.0" />
                            <kd value="1000.0" />
                        </ode>
                    </friction>
                </surface>

            </collision> -->
  </gazebo>
  <gazebo reference="r_pel_link">
    <mu1>1.0</mu1>
    <mu2>1.0</mu2>
    <self_collide>0</self_collide>
    <material>Gazebo/White</material>
    <visual>
      <material>
        <ambient>0.7 0.7 0.7 1</ambient>
        <diffuse>0.7 0.7 0.7 1</diffuse>
        <specular>0.1 0.1 0.1 1</specular>
        <emissive>0 0 0 0</emissive>
      </material>
    </visual>
    <!-- <collision>
                <surface>
                    <friction>
                        <ode>
                            <mu1>2</mu1>
                            <mu2>2</mu2>
                            <kp value="1000000.0" />
                            <kd value="1000.0" />
                        </ode>
                    </friction>
                </surface>

            </collision> -->
  </gazebo>
  <gazebo reference="r_thigh_link">
    <mu1>1.0</mu1>
    <mu2>1.0</mu2>
    <self_collide>0</self_collide>
    <material>Gazebo/White</material>
    <visual>
      <material>
        <ambient>0.7 0.7 0.7 1</ambient>
        <diffuse>0.7 0.7 0.7 1</diffuse>
        <specular>0.1 0.1 0.1 1</specular>
        <emissive>0 0 0 0</emissive>
      </material>
    </visual>
    <!-- <collision>
                <surface>
                    <friction>
                        <ode>
                            <mu1>2</mu1>
                            <mu2>2</mu2>
                            <kp value="1000000.0" />
                            <kd value="1000.0" />
                        </ode>
                    </friction>
                </surface>

            </collision> -->
  </gazebo>
  <gazebo reference="r_shank_link">
    <mu1>1.0</mu1>
    <mu2>1.0</mu2>
    <self_collide>0</self_collide>
    <material>Gazebo/White</material>
    <visual>
      <material>
        <ambient>0.7 0.7 0.7 1</ambient>
        <diffuse>0.7 0.7 0.7 1</diffuse>
        <specular>0.1 0.1 0.1 1</specular>
        <emissive>0 0 0 0</emissive>
      </material>
    </visual>
    <!-- <collision>
                <surface>
                    <friction>
                        <ode>
                            <mu1>2</mu1>
                            <mu2>2</mu2>
                            <kp value="1000000.0" />
                            <kd value="1000.0" />
                        </ode>
                    </friction>
                </surface>

            </collision> -->
  </gazebo>
  <gazebo reference="r_foot_link">
    <mu1>1.0</mu1>
    <mu2>1.0</mu2>
    <self_collide>0</self_collide>
    <material>Gazebo/White</material>
    <visual>
      <material>
        <ambient>0.7 0.7 0.7 1</ambient>
        <diffuse>0.7 0.7 0.7 1</diffuse>
        <specular>0.1 0.1 0.1 1</specular>
        <emissive>0 0 0 0</emissive>
      </material>
    </visual>
    <!-- <collision>
                <surface>
                    <friction>
                        <ode>
                            <mu1>2</mu1>
                            <mu2>2</mu2>
                            <kp value="1000000.0" />
                            <kd value="1000.0" />
                        </ode>
                    </friction>
                </surface>

            </collision> -->
  </gazebo>
  <!-- 
  <xacro:define_gazebo_material link_name="stand_base" r="0.4" g="0.4" b="0.4" a="0.5" />
  <xacro:define_gazebo_material link_name="support_pole" r="0.4" g="0.4" b="0.4" a="0.5" />
 -->
  <gazebo reference="l_pel_link">
    <gravity>true</gravity>
    <sensor name="yr_l_pel_joint" type="imu">
      <always_on>true</always_on>
      <update_rate>100</update_rate>
      <visualize>true</visualize>
      <topic>yr_l_pel_joint/imu_data</topic>
      <plugin filename="libgazebo_ros_imu_sensor.so" name="imu_plugin">
        <topicName>yr_l_pel_joint/imu_data</topicName>
        <bodyName>yr_l_pel_joint_imu</bodyName>
        <updateRateHZ>10.0</updateRateHZ>
        <gaussianNoise>0.0</gaussianNoise>
        <xyzOffset>0 0 0</xyzOffset>
        <rpyOffset>0 0 0</rpyOffset>
        <frameName>yr_l_pel_joint_imu</frameName>
        <initialOrientationAsReference>false</initialOrientationAsReference>
      </plugin>
      <pose>0 0 0 0 0 0</pose>
    </sensor>
  </gazebo>
  <gazebo reference="l_thigh_link">
    <gravity>true</gravity>
    <sensor name="yr_l_hip_joint" type="imu">
      <always_on>true</always_on>
      <update_rate>100</update_rate>
      <visualize>true</visualize>
      <topic>yr_l_hip_joint/imu_data</topic>
      <plugin filename="libgazebo_ros_imu_sensor.so" name="imu_plugin">
        <topicName>yr_l_hip_joint/imu_data</topicName>
        <bodyName>yr_l_hip_joint_imu</bodyName>
        <updateRateHZ>10.0</updateRateHZ>
        <gaussianNoise>0.0</gaussianNoise>
        <xyzOffset>0 0 0</xyzOffset>
        <rpyOffset>0 0 0</rpyOffset>
        <frameName>yr_l_hip_joint_imu</frameName>
        <initialOrientationAsReference>false</initialOrientationAsReference>
      </plugin>
      <pose>0 0 0 0 0 0</pose>
    </sensor>
  </gazebo>
  <gazebo reference="l_shank_link">
    <gravity>true</gravity>
    <sensor name="yr_l_kne_joint" type="imu">
      <always_on>true</always_on>
      <update_rate>100</update_rate>
      <visualize>true</visualize>
      <topic>yr_l_kne_joint/imu_data</topic>
      <plugin filename="libgazebo_ros_imu_sensor.so" name="imu_plugin">
        <topicName>yr_l_kne_joint/imu_data</topicName>
        <bodyName>yr_l_kne_joint_imu</bodyName>
        <updateRateHZ>10.0</updateRateHZ>
        <gaussianNoise>0.0</gaussianNoise>
        <xyzOffset>0 0 0</xyzOffset>
        <rpyOffset>0 0 0</rpyOffset>
        <frameName>yr_l_kne_joint_imu</frameName>
        <initialOrientationAsReference>false</initialOrientationAsReference>
      </plugin>
      <pose>0 0 0 0 0 0</pose>
    </sensor>
  </gazebo>
  <gazebo reference="l_foot_link">
    <gravity>true</gravity>
    <sensor name="yr_l_ank_joint" type="imu">
      <always_on>true</always_on>
      <update_rate>100</update_rate>
      <visualize>true</visualize>
      <topic>yr_l_ank_joint/imu_data</topic>
      <plugin filename="libgazebo_ros_imu_sensor.so" name="imu_plugin">
        <topicName>yr_l_ank_joint/imu_data</topicName>
        <bodyName>yr_l_ank_joint_imu</bodyName>
        <updateRateHZ>10.0</updateRateHZ>
        <gaussianNoise>0.0</gaussianNoise>
        <xyzOffset>0 0 0</xyzOffset>
        <rpyOffset>0 0 0</rpyOffset>
        <frameName>yr_l_ank_joint_imu</frameName>
        <initialOrientationAsReference>false</initialOrientationAsReference>
      </plugin>
      <pose>0 0 0 0 0 0</pose>
    </sensor>
  </gazebo>
  <gazebo reference="r_pel_link">
    <gravity>true</gravity>
    <sensor name="yr_r_pel_joint" type="imu">
      <always_on>true</always_on>
      <update_rate>100</update_rate>
      <visualize>true</visualize>
      <topic>yr_r_pel_joint/imu_data</topic>
      <plugin filename="libgazebo_ros_imu_sensor.so" name="imu_plugin">
        <topicName>yr_r_pel_joint/imu_data</topicName>
        <bodyName>yr_r_pel_joint_imu</bodyName>
        <updateRateHZ>10.0</updateRateHZ>
        <gaussianNoise>0.0</gaussianNoise>
        <xyzOffset>0 0 0</xyzOffset>
        <rpyOffset>0 0 0</rpyOffset>
        <frameName>yr_r_pel_joint_imu</frameName>
        <initialOrientationAsReference>false</initialOrientationAsReference>
      </plugin>
      <pose>0 0 0 0 0 0</pose>
    </sensor>
  </gazebo>
  <gazebo reference="r_thigh_link">
    <gravity>true</gravity>
    <sensor name="yr_r_hip_joint" type="imu">
      <always_on>true</always_on>
      <update_rate>100</update_rate>
      <visualize>true</visualize>
      <topic>yr_r_hip_joint/imu_data</topic>
      <plugin filename="libgazebo_ros_imu_sensor.so" name="imu_plugin">
        <topicName>yr_r_hip_joint/imu_data</topicName>
        <bodyName>yr_r_hip_joint_imu</bodyName>
        <updateRateHZ>10.0</updateRateHZ>
        <gaussianNoise>0.0</gaussianNoise>
        <xyzOffset>0 0 0</xyzOffset>
        <rpyOffset>0 0 0</rpyOffset>
        <frameName>yr_r_hip_joint_imu</frameName>
        <initialOrientationAsReference>false</initialOrientationAsReference>
      </plugin>
      <pose>0 0 0 0 0 0</pose>
    </sensor>
  </gazebo>
  <gazebo reference="r_shank_link">
    <gravity>true</gravity>
    <sensor name="yr_r_kne_joint" type="imu">
      <always_on>true</always_on>
      <update_rate>100</update_rate>
      <visualize>true</visualize>
      <topic>yr_r_kne_joint/imu_data</topic>
      <plugin filename="libgazebo_ros_imu_sensor.so" name="imu_plugin">
        <topicName>yr_r_kne_joint/imu_data</topicName>
        <bodyName>yr_r_kne_joint_imu</bodyName>
        <updateRateHZ>10.0</updateRateHZ>
        <gaussianNoise>0.0</gaussianNoise>
        <xyzOffset>0 0 0</xyzOffset>
        <rpyOffset>0 0 0</rpyOffset>
        <frameName>yr_r_kne_joint_imu</frameName>
        <initialOrientationAsReference>false</initialOrientationAsReference>
      </plugin>
      <pose>0 0 0 0 0 0</pose>
    </sensor>
  </gazebo>
  <gazebo reference="r_foot_link">
    <gravity>true</gravity>
    <sensor name="yr_r_ank_joint" type="imu">
      <always_on>true</always_on>
      <update_rate>100</update_rate>
      <visualize>true</visualize>
      <topic>yr_r_ank_joint/imu_data</topic>
      <plugin filename="libgazebo_ros_imu_sensor.so" name="imu_plugin">
        <topicName>yr_r_ank_joint/imu_data</topicName>
        <bodyName>yr_r_ank_joint_imu</bodyName>
        <updateRateHZ>10.0</updateRateHZ>
        <gaussianNoise>0.0</gaussianNoise>
        <xyzOffset>0 0 0</xyzOffset>
        <rpyOffset>0 0 0</rpyOffset>
        <frameName>yr_r_ank_joint_imu</frameName>
        <initialOrientationAsReference>false</initialOrientationAsReference>
      </plugin>
      <pose>0 0 0 0 0 0</pose>
    </sensor>
  </gazebo>
  <!-- 
  <xacro:include filename="$(find realsense_ros_gazebo)/xacro/depthcam.xacro"/>

  <xacro:realsense_d435 sensor_name="d435_front" parent_link="l_thigh_link" rate="10">
    <origin rpy="${PI/2} ${PI/3} 0 " xyz="0 0 ${-thigh_l/2}"/>
  </xacro:realsense_d435>

  <xacro:realsense_d435 sensor_name="d435_back" parent_link="l_thigh_link" rate="10">
    <origin rpy="${PI/2} ${PI/3} ${PI}" xyz="0 0 ${-thigh_l/2}"/>
  </xacro:realsense_d435> -->
</robot>

